Workbook

Sheet Summary
A1: Inventory With More Than a Year of Supply
A2: Pulled from NetSuite 10/23/2026. Items that sold in the last 12 months but have more on hand than they sold all year. Value at average cost. Dead stock (no sales at all) is not in here.
A4: Items | B4: =COUNTA(Items!A2:A6476) -> 6475
A5: Value on hand | B5: =SUM(Items!F2:F6476) -> 908669.4
A6: Bought again in the last 12 months (last PO dated after 10/23/2025) | B6: =COUNTIFS(Items!K2:K6476,">="&DATE(2025,10,23)) -> 1798
A7: Value on hand of those | B7: =SUMIFS(Items!F2:F6476,Items!K2:K6476,">="&DATE(2025,10,23)) -> 303323.63
A9: By years of supply
A10: Years of supply | B10: Items | C10: Value on hand
A11: 1 to 2 | B11: =COUNTIFS(Items!H2:H6476,">="&1,Items!H2:H6476,"<"&2) -> 1147 | C11: =SUMIFS(Items!F2:F6476,Items!H2:H6476,">="&1,Items!H2:H6476,"<"&2) -> 166069.26
A12: 2 to 5 | B12: =COUNTIFS(Items!H2:H6476,">="&2,Items!H2:H6476,"<"&5) -> 1580 | C12: =SUMIFS(Items!F2:F6476,Items!H2:H6476,">="&2,Items!H2:H6476,"<"&5) -> 169742.8
A13: 5 to 10 | B13: =COUNTIFS(Items!H2:H6476,">="&5,Items!H2:H6476,"<"&10) -> 1126 | C13: =SUMIFS(Items!F2:F6476,Items!H2:H6476,">="&5,Items!H2:H6476,"<"&10) -> 145940.03
A14: 10+ | B14: =COUNTIFS(Items!H2:H6476,">="&10,Items!H2:H6476,"<"&1000000000) -> 2622 | C14: =SUMIFS(Items!F2:F6476,Items!H2:H6476,">="&10,Items!H2:H6476,"<"&1000000000) -> 426917.31
A16: By vendor on the last PO (top 15)
A17: Vendor | B17: Items | C17: Value on hand
A18: VN30 Freudenberg | B18: =COUNTIFS(Items!L2:L6476,"VN30 Freudenberg") -> 879 | C18: =SUMIFS(Items!F2:F6476,Items!L2:L6476,"VN30 Freudenberg") -> 195297.05
A19: VN82 Tuico Products Joint Stock Company | B19: =COUNTIFS(Items!L2:L6476,"VN82 Tuico Products Joint Stock Company") -> 796 | C19: =SUMIFS(Items!F2:F6476,Items!L2:L6476,"VN82 Tuico Products Joint Stock Company") -> 130827.29
A20: VN10 GE MAO RUBBER INDUSTRIAL CO., LTD . | B20: =COUNTIFS(Items!L2:L6476,"VN10 GE MAO RUBBER INDUSTRIAL CO., LTD .") -> 1039 | C20: =SUMIFS(Items!F2:F6476,Items!L2:L6476,"VN10 GE MAO RUBBER INDUSTRIAL CO., LTD .") -> 107366.91
A21: (no PO on file) | B21: =COUNTIFS(Items!L2:L6476,"") -> 1299 | C21: =SUMIFS(Items!F2:F6476,Items!L2:L6476,"") -> 105349.32
A22: VN01 Seal and Rubber Technologies | B22: =COUNTIFS(Items!L2:L6476,"VN01 Seal and Rubber Technologies") -> 663 | C22: =SUMIFS(Items!F2:F6476,Items!L2:L6476,"VN01 Seal and Rubber Technologies") -> 89621.79
A23: VN12 AnySeals, Inc | B23: =COUNTIFS(Items!L2:L6476,"VN12 AnySeals, Inc") -> 832 | C23: =SUMIFS(Items!F2:F6476,Items!L2:L6476,"VN12 AnySeals, Inc") -> 56755.22
A24: VN11 Best Ring Industrial Corporation | B24: =COUNTIFS(Items!L2:L6476,"VN11 Best Ring Industrial Corporation") -> 120 | C24: =SUMIFS(Items!F2:F6476,Items!L2:L6476,"VN11 Best Ring Industrial Corporation") -> 47287.05
A25: VN53 Ningbo Quantum Seal | B25: =COUNTIFS(Items!L2:L6476,"VN53 Ningbo Quantum Seal") -> 157 | C25: =SUMIFS(Items!F2:F6476,Items!L2:L6476,"VN53 Ningbo Quantum Seal") -> 22805.19
A26: VN772 Universal Polymer & Rubber, LTD. | B26: =COUNTIFS(Items!L2:L6476,"VN772 Universal Polymer & Rubber, LTD.") -> 12 | C26: =SUMIFS(Items!F2:F6476,Items!L2:L6476,"VN772 Universal Polymer & Rubber, LTD.") -> 22784.76
A27: VN67 Precix | B27: =COUNTIFS(Items!L2:L6476,"VN67 Precix") -> 75 | C27: =SUMIFS(Items!F2:F6476,Items!L2:L6476,"VN67 Precix") -> 20608.63
A28: VN29 Flambeau Products Corp | B28: =COUNTIFS(Items!L2:L6476,"VN29 Flambeau Products Corp") -> 9 | C28: =SUMIFS(Items!F2:F6476,Items!L2:L6476,"VN29 Flambeau Products Corp") -> 16071.46
A29: VN90 Xlong Seal Co | B29: =COUNTIFS(Items!L2:L6476,"VN90 Xlong Seal Co") -> 62 | C29: =SUMIFS(Items!F2:F6476,Items!L2:L6476,"VN90 Xlong Seal Co") -> 10724.03
A30: VN05 APG | B30: =COUNTIFS(Items!L2:L6476,"VN05 APG") -> 88 | C30: =SUMIFS(Items!F2:F6476,Items!L2:L6476,"VN05 APG") -> 10594.47
A31: VN24 Engineered Seals & Components LLC | B31: =COUNTIFS(Items!L2:L6476,"VN24 Engineered Seals & Components LLC") -> 56 | C31: =SUMIFS(Items!F2:F6476,Items!L2:L6476,"VN24 Engineered Seals & Components LLC") -> 7676.11
A32: VN07 Boyd Corporation | B32: =COUNTIFS(Items!L2:L6476,"VN07 Boyd Corporation") -> 28 | C32: =SUMIFS(Items!F2:F6476,Items!L2:L6476,"VN07 Boyd Corporation") -> 7649.08
A34: By class (top 15)
A35: Class | B35: Items | C35: Value on hand
A36: Metric MN70 | B36: =COUNTIFS(Items!C2:C6476,"Metric MN70") -> 1125 | C36: =SUMIFS(Items!F2:F6476,Items!C2:C6476,"Metric MN70") -> 91121.3
A37: AS568 B70 | B37: =COUNTIFS(Items!C2:C6476,"AS568 B70") -> 198 | C37: =SUMIFS(Items!F2:F6476,Items!C2:C6476,"AS568 B70") -> 58177.3
A38: AS568 V75 | B38: =COUNTIFS(Items!C2:C6476,"AS568 V75") -> 180 | C38: =SUMIFS(Items!F2:F6476,Items!C2:C6476,"AS568 V75") -> 46244.43
A39: Metric MV75 | B39: =COUNTIFS(Items!C2:C6476,"Metric MV75") -> 584 | C39: =SUMIFS(Items!F2:F6476,Items!C2:C6476,"Metric MV75") -> 44566.82
A40: AS568 A75 | B40: =COUNTIFS(Items!C2:C6476,"AS568 A75") -> 132 | C40: =SUMIFS(Items!F2:F6476,Items!C2:C6476,"AS568 A75") -> 31698.53
A41: AS568 S70 | B41: =COUNTIFS(Items!C2:C6476,"AS568 S70") -> 184 | C41: =SUMIFS(Items!F2:F6476,Items!C2:C6476,"AS568 S70") -> 25642.33
A42: AS568 E70-NSF | B42: =COUNTIFS(Items!C2:C6476,"AS568 E70-NSF") -> 119 | C42: =SUMIFS(Items!F2:F6476,Items!C2:C6476,"AS568 E70-NSF") -> 25247.09
A43: AS568 B90 | B43: =COUNTIFS(Items!C2:C6476,"AS568 B90") -> 213 | C43: =SUMIFS(Items!F2:F6476,Items!C2:C6476,"AS568 B90") -> 25082.1
A44: AS568 BV75 | B44: =COUNTIFS(Items!C2:C6476,"AS568 BV75") -> 143 | C44: =SUMIFS(Items!F2:F6476,Items!C2:C6476,"AS568 BV75") -> 24239.42
...

Sheet Items
A1: Item | B1: Description | C1: Class | D1: Qty on hand | E1: Unit cost | F1: Value on hand | G1: Sold last 12 mo (qty) | H1: Years of supply | I1: Last sold | J1: Last PO # | K1: PO date written | L1: PO vendor | M1: PO qty | N1: PO price each | O1: PO line total
A2: UC70011 | C2: AS568 UC70 | D2: 38372 | E2: 0.1475 | F2: =D2*E2 -> 5659.87 | G2: 2719 | H2: =IF(G2>0,D2/G2,"") -> 14.112541 | I2: 46316 | J2: 30570 | K2: 44292 | L2: VN30 Freudenberg | M2: 50000 | N2: 0.1475 | O2: =M2*N2 -> 7375
A3: FS70116 | C3: AS568 FS70 | D3: 27695 | E3: 0.20356274 | F3: =D3*E3 -> 5637.67 | G3: 14975 | H3: =IF(G3>0,D3/G3,"") -> 1.8494157 | I3: 46260 | J3: 34607 | K3: 46065 | L3: VN67 Precix | M3: 15000 | N3: 0 | O3: 2966.64
A4: B70010 | C4: AS568 B70 | D4: 1741405 | E4: 0.0031085933 | F4: =D4*E4 -> 5413.32 | G4: 1216904 | H4: =IF(G4>0,D4/G4,"") -> 1.4310126 | I4: 46315 | J4: 34938 | K4: 46227 | L4: VN30 Freudenberg | M4: 1500000 | N4: 0.0032 | O4: =M4*N4 -> 4800
A5: C166-36 36-Hole | C5: OSK™ Kits | D5: 473 | E5: 11.3 | F5: =D5*E5 -> 5344.9 | G5: 393 | H5: =IF(G5>0,D5/G5,"") -> 1.2035623 | I5: 46184 | J5: 34877 | K5: 46199 | L5: VN29 Flambeau Products Corp | M5: 504 | N5: 11.3 | O5: =M5*N5 -> 5695.2
A6: S70.375 | C6: Cord S70 | D6: 5088 | E6: 0.96229953 | F6: =D6*E6 -> 4896.18 | G6: 2801 | H6: =IF(G6>0,D6/G6,"") -> 1.8164941 | I6: 46316 | J6: 34945 | K6: 46231 | L6: VN772 Universal Polymer & Rubber, LTD. | M6: 5000 | N6: 0.964 | O6: =M6*N6 -> 4820
A7: S50.394 | C7: Cord S50 | D7: 5015 | E7: 0.96270189 | F7: =D7*E7 -> 4827.95 | G7: 616 | H7: =IF(G7>0,D7/G7,"") -> 8.1412338 | I7: 46177 | J7: 34582 | K7: 46057 | L7: VN772 Universal Polymer & Rubber, LTD. | M7: 5000 | N7: 0.964 | O7: =M7*N7 -> 4820
A8: N1.10X004 | C8: Metric MN70 | D8: 495674 | E8: 0.0093300637 | F8: =D8*E8 -> 4624.67 | G8: 624 | H8: =IF(G8>0,D8/G8,"") -> 794.34936 | I8: 46237 | J8: 30871 | K8: 44385 | L8: VN82 Tuico Products Joint Stock Company | M8: 623000 | N8: 0.00933 | O8: =M8*N8 -> 5812.59
A9: C200 18-Hole 8 X 4 Blue | C9: OSK™ Kits | D9: 889 | E9: 4.09 | F9: =D9*E9 -> 3636.01 | G9: 536 | H9: =IF(G9>0,D9/G9,"") -> 1.6585821 | I9: 46183 | J9: 34847 | K9: 46185 | L9: VN29 Flambeau Products Corp | M9: 1008 | N9: 4.09 | O9: =M9*N9 -> 4122.72
A10: QV-113 | C10: AS568 QV | D10: 38678 | E10: 0.093809659 | F10: =D10*E10 -> 3628.37 | G10: 25 | H10: =IF(G10>0,D10/G10,"") -> 1547.12 | I10: 46008 | J10: 32322 | K10: 44887 | L10: VN12 AnySeals, Inc | M10: 4150 | N10: 0.1885 | O10: =M10*N10 -> 782.275
A11: B70014 | C11: AS568 B70 | D11: 1146388 | E11: 0.0031517689 | F11: =D11*E11 -> 3613.15 | G11: 175853 | H11: =IF(G11>0,D11/G11,"") -> 6.519013 | I11: 46315 | J11: 33284 | K11: 45304 | L11: VN01 Seal and Rubber Technologies | M11: 400000 | N11: 0.0033 | O11: =M11*N11 -> 1320
A12: B90153 | C12: AS568 B90 | D12: 41871 | E12: 0.08 | F12: =D12*E12 -> 3349.68 | G12: 162 | H12: =IF(G12>0,D12/G12,"") -> 258.46296 | I12: 46231
A13: N70.500 | C13: Cord N70 | D13: 3495 | E13: 0.88475536 | F13: =D13*E13 -> 3092.22 | G13: 1662 | H13: =IF(G13>0,D13/G13,"") -> 2.1028881 | I13: 46310 | J13: 34019 | K13: 45688 | L13: VN772 Universal Polymer & Rubber, LTD. | M13: 5200 | N13: 0.885 | O13: =M13*N13 -> 4602
A14: E70036-NSF | C14: AS568 E70-NSF | D14: 65919 | E14: 0.044678772 | F14: =D14*E14 -> 2945.18 | G14: 65 | H14: =IF(G14>0,D14/G14,"") -> 1014.1385 | I14: 46317 | J14: 33335 | K14: 45325 | L14: VN82 Tuico Products Joint Stock Company | M14: 57125 | N14: 0.04442 | O14: =M14*N14 -> 2537.4925
A15: E70026-NSF | C15: AS568 E70-NSF | D15: 134649 | E15: 0.020536283 | F15: =D15*E15 -> 2765.19 | G15: 110080 | H15: =IF(G15>0,D15/G15,"") -> 1.2231922 | I15: 46304 | J15: 34589 | K15: 46055 | L15: VN10 GE MAO RUBBER INDUSTRIAL CO., LTD . | M15: 30000 | N15: 0.0294 | O15: =M15*N15 -> 882
A16: B90248 | C16: AS568 B90 | D16: 38499 | E16: 0.07 | F16: =D16*E16 -> 2694.93 | G16: 232 | H16: =IF(G16>0,D16/G16,"") -> 165.94397 | I16: 46297
A17: B70015 | C17: AS568 B70 | D17: 1068341 | E17: 0.0024530557 | F17: =D17*E17 -> 2620.7 | G17: 154105 | H17: =IF(G17>0,D17/G17,"") -> 6.9325525 | I17: 46314 | J17: 32477 | K17: 44957 | L17: VN82 Tuico Products Joint Stock Company | M17: 1000000 | N17: 0.00276 | O17: =M17*N17 -> 2760
A18: ACCUTEK-A-11275 | C18: Special Order | D18: 1998 | E18: 1.2 | F18: =D18*E18 -> 2397.6 | G18: 1002 | H18: =IF(G18>0,D18/G18,"") -> 1.994012 | I18: 46283 | J18: 33594 | K18: 45435 | L18: VN53 Ningbo Quantum Seal | M18: 4000 | N18: 1.2 | O18: =M18*N18 -> 4800
A19: V75012 | C19: AS568 V75 | D19: 156897 | E19: 0.014581095 | F19: =D19*E19 -> 2287.73 | G19: 26638 | H19: =IF(G19>0,D19/G19,"") -> 5.8899692 | I19: 46317 | J19: 31446 | K19: 44600 | L19: VN07 Boyd Corporation | M19: 188899 | N19: 0.0168 | O19: 3169.8408
A20: CV75013 | C20: AS568 CV75 | D20: 7804 | E20: 0.28389928 | F20: =D20*E20 -> 2215.55 | G20: 7588 | H20: =IF(G20>0,D20/G20,"") -> 1.028466 | I20: 46310 | J20: 34400 | K20: 45937 | L20: VN67 Precix | M20: 908 | N20: 0.3194 | O20: =M20*N20 -> 290.0152
A21: UC90006 | C21: AS568 UC90 | D21: 19244 | E21: 0.1145001 | F21: =D21*E21 -> 2203.44 | G21: 1747 | H21: =IF(G21>0,D21/G21,"") -> 11.015455 | I21: 46308 | J21: 30792 | K21: 44363 | L21: VN70 Real Seal Co Inc | M21: 25000 | N21: 0.0795 | O21: =M21*N21 -> 1987.5
A22: S70155 | C22: AS568 S70 | D22: 18159 | E22: 0.11963985 | F22: =D22*E22 -> 2172.54 | G22: 203 | H22: =IF(G22>0,D22/G22,"") -> 89.453202 | I22: 46163 | J22: 32099 | K22: 44811 | L22: VN82 Tuico Products Joint Stock Company | M22: 29465 | N22: 0.11964 | O22: =M22*N22 -> 3525.1926
A23: K382-BOX | D23: 602 | E23: 3.6 | F23: =D23*E23 -> 2167.2 | G23: 313 | H23: =IF(G23>0,D23/G23,"") -> 1.9233227 | I23: 46181 | J23: 35005 | K23: 46253 | L23: VN11 Best Ring Industrial Corporation | M23: 1000 | N23: 5 | O23: =M23*N23 -> 5000
A24: UC90908 | C24: AS568 UC90 | D24: 6116 | E24: 0.34756704 | F24: =D24*E24 -> 2125.72 | G24: 1799 | H24: =IF(G24>0,D24/G24,"") -> 3.3996665 | I24: 46190 | J24: 34744 | K24: 46134 | L24: VN30 Freudenberg | M24: 5000 | N24: 0.3445 | O24: =M24*N24 -> 1722.5
A25: FFKM-005-SZ485 | C25: AS568 FFKM-485 | D25: 498 | E25: 4.1606827 | F25: =D25*E25 -> 2072.02 | G25: 1 | H25: =IF(G25>0,D25/G25,"") -> 498 | I25: 46212 | J25: 32965 | K25: 45138 | L25: VN30 Freudenberg | M25: 507 | N25: 0 | O25: 2110
A26: V75018 | C26: AS568 V75 | D26: 72900 | E26: 0.028269959 | F26: =D26*E26 -> 2060.88 | G26: 48160 | H26: =IF(G26>0,D26/G26,"") -> 1.5137043 | I26: 46314 | J26: 34925 | K26: 46224 | L26: VN01 Seal and Rubber Technologies | M26: 78855 | N26: 0.0283 | O26: =M26*N26 -> 2231.5965
A27: S70016 | C27: AS568 S70 | D27: 368374 | E27: 0.0054827431 | F27: =D27*E27 -> 2019.7 | G27: 6961 | H27: =IF(G27>0,D27/G27,"") -> 52.919695 | I27: 46304 | J27: 30577 | K27: 44294 | L27: VN12 AnySeals, Inc | M27: 364648 | N27: 0.0056 | O27: =M27*N27 -> 2042.0288
A28: QR-106 | C28: AS568 QR | D28: 106401 | E28: 0.018800293 | F28: =D28*E28 -> 2000.37 | G28: 93 | H28: =IF(G28>0,D28/G28,"") -> 1144.0968 | I28: 46099
A29: E70.394 | C29: Cord E70 | D29: 4847 | E29: 0.40700021 | F29: =D29*E29 -> 1972.73 | G29: 251 | H29: =IF(G29>0,D29/G29,"") -> 19.310757 | I29: 46156 | J29: 34436 | K29: 45959 | L29: VN772 Universal Polymer & Rubber, LTD. | M29: 5000 | N29: 0.407 | O29: =M29*N29 -> 2035
A30: V75017 | C30: AS568 V75 | D30: 64677 | E30: 0.029757719 | F30: =D30*E30 -> 1924.64 | G30: 18444 | H30: =IF(G30>0,D30/G30,"") -> 3.5066688 | I30: 46317 | J30: 32361 | K30: 44914 | L30: VN30 Freudenberg | M30: 70169 | N30: 0.014 | O30: =M30*N30 -> 982.366
A31: S70.275-VN772 | C31: Cord S70 | D31: 3000 | E31: 0.612 | F31: =D31*E31 -> 1836 | G31: 3000 | H31: =IF(G31>0,D31/G31,"") -> 1 | I31: 46294 | J31: 34855 | K31: 46188 | L31: VN772 Universal Polymer & Rubber, LTD. | M31: 6000 | N31: 0.612 | O31: =M31*N31 -> 3672
A32: UC90916 | C32: AS568 UC90 | D32: 2972 | E32: 0.60459287 | F32: =D32*E32 -> 1796.85 | G32: 1151 | H32: =IF(G32>0,D32/G32,"") -> 2.5821025 | I32: 46300 | J32: 34744 | K32: 46134 | L32: VN30 Freudenberg | M32: 2500 | N32: 0.5816 | O32: =M32*N32 -> 1454
A33: SN70.275 | C33: Cord SN70 | D33: 4065 | E33: 0.43499877 | F33: =D33*E33 -> 1768.27 | G33: 525 | H33: =IF(G33>0,D33/G33,"") -> 7.7428571 | I33: 46288 | J33: 34130 | K33: 45763 | L33: VN772 Universal Polymer & Rubber, LTD. | M33: 5000 | N33: 0.435 | O33: =M33*N33 -> 2175
A34: B70113 | C34: AS568 B70 | D34: 255733 | E34: 0.0068860491 | F34: =D34*E34 -> 1760.99 | G34: 46520 | H34: =IF(G34>0,D34/G34,"") -> 5.49727 | I34: 46316 | J34: 31834 | K34: 44719 | L34: VN82 Tuico Products Joint Stock Company | M34: 38571 | N34: 0.00444 | O34: =M34*N34 -> 171.25524
A35: FFKM-007-SZ485 | C35: AS568 FFKM-485 | D35: 487 | E35: 3.5987064 | F35: =D35*E35 -> 1752.57 | G35: 108 | H35: =IF(G35>0,D35/G35,"") -> 4.5092593 | I35: 46315 | J35: 33611 | K35: 45447 | L35: VN30 Freudenberg | M35: 260 | N35: 3.9665 | O35: =M35*N35 -> 1031.29
A36: BV75331 | C36: AS568 BV75 | D36: 2750 | E36: 0.63313455 | F36: =D36*E36 -> 1741.12 | G36: 527 | H36: =IF(G36>0,D36/G36,"") -> 5.2182163 | I36: 46142 | J36: 33302 | K36: 45316 | L36: VN01 Seal and Rubber Technologies | M36: 1200 | N36: 0.6491 | O36: =M36*N36 -> 778.92
A37: N1.00X002.5 | C37: Metric MN70 | D37: 314992 | E37: 0.0054001054 | F37: =D37*E37 -> 1700.99 | G37: 9525 | H37: =IF(G37>0,D37/G37,"") -> 33.070026 | I37: 46316 | J37: 32335 | K37: 44902 | L37: VN12 AnySeals, Inc | M37: 492716 | N37: 0.0054 | O37: =M37*N37 -> 2660.6664
A38: C203 6-Hole 8 X 4 | D38: 403 | E38: 4.15 | F38: =D38*E38 -> 1672.45 | G38: 58 | H38: =IF(G38>0,D38/G38,"") -> 6.9482759 | I38: 46175 | J38: 34593 | K38: 46062 | L38: VN29 Flambeau Products Corp | M38: 504 | N38: 4.15 | O38: =M38*N38 -> 2091.6
A39: V75003 | C39: AS568 V75 | D39: 276313 | E39: 0.0060300456 | F39: =D39*E39 -> 1666.18 | G39: 1110 | H39: =IF(G39>0,D39/G39,"") -> 248.93063 | I39: 46283 | J39: 30674 | K39: 44323 | L39: VN10 GE MAO RUBBER INDUSTRIAL CO., LTD . | M39: 143173 | N39: 0.0065 | O39: =M39*N39 -> 930.6245
A40: N38.00X1116.59-CM | C40: Continuously Molded | D40: 5 | E40: 333.12 | F40: =D40*E40 -> 1665.6 | G40: 5 | H40: =IF(G40>0,D40/G40,"") -> 1 | I40: 46196 | J40: 34685 | K40: 46105 | L40: VN72 Sealcore Operations, LLC | M40: 5 | N40: 333.12 | O40: =M40*N40 -> 1665.6
...
