Workbook

Sheet Summary
A1: Get Even by January 1: Cash Plan Summary
A2: Built 10/23/2026 from the AP schedule, FY2026 income statement, balance sheets, and NetSuite receipts. Rough plan, not accounting.
A4: Plan | B4: Lowest cash in 13 weeks | C4: Cash on Jan 22 | D4: Past-due bills left | E4: PayPal loan still owed | F4: Weeks below $40K floor
A5: PLAN A: Keep doing what we're doing (no cuts, no loan) | B5: =MIN('13-Week Forecast'!B26:N26) -> -118397.58 | C5: ='13-Week Forecast'!N26 -> -118397.58 | D5: =Assumptions!$B$16-'13-Week Forecast'!O19 -> 0 | E5: ='13-Week Forecast'!N27 -> 0 | F5: =COUNTIF('13-Week Forecast'!B28:N28,"YES") -> 13
A6: PLAN B: Tighten up (buy less, cut software, sell dead stock, vendor payment plans) | B6: =MIN('13-Week Forecast'!B46:N46) -> -61238.855 | C6: ='13-Week Forecast'!N46 -> 15923.401 | D6: =Assumptions!$B$16-'13-Week Forecast'!O39 -> 0 | E6: ='13-Week Forecast'!N47 -> 0 | F6: =COUNTIF('13-Week Forecast'!B48:N48,"YES") -> 13
A7: PLAN C: Tighten up + PayPal loan (pay off past-due bills now) | B7: =MIN('13-Week Forecast'!B66:N66) -> 21699.189 | C7: ='13-Week Forecast'!N66 -> 78818.401 | D7: =Assumptions!$B$16-'13-Week Forecast'!O59 -> 0 | E7: ='13-Week Forecast'!N67 -> 92895 | F7: =COUNTIF('13-Week Forecast'!B68:N68,"YES") -> 7
A8: PLAN D: PayPal loan only, no other changes | B8: =MIN('13-Week Forecast'!B86:N86) -> -40502.58 | C8: ='13-Week Forecast'!N86 -> -40502.58 | D8: =Assumptions!$B$16-'13-Week Forecast'!O79 -> 0 | E8: ='13-Week Forecast'!N87 -> 92895 | F8: =COUNTIF('13-Week Forecast'!B88:N88,"YES") -> 12
A10: How to read this:
A11: Plan A: business as usual. We make money, but the past-due bills only get caught up by paying a little extra each week.
A12: Plan B: same sales, but we buy 25% less inventory until January, trim software, sell some dead stock, and agree payment plans with vendors.
A13: Plan C: Plan B plus a PayPal Working Capital loan to pay the past-due bills right away. PayPal then takes 10% of PayPal sales until it's repaid.
A14: Plan D: the PayPal loan by itself with no other changes. Shows whether a loan alone gets us there.
A16: Not in this forecast: Groundwork (no more money goes there), big one-time buys, tax payments, owner draws. Add them on the forecast tab if they come up.
A17: The PayPal fee is a guess (10%). Plug in the real number from PayPal's offer on the Assumptions tab.
A18: Late fees we stop paying (about $3K/month this year) are a bonus on top of Plans B and C.

Sheet Assumptions
A1: 13-Week Cash Forecast: Assumptions (yellow cells can be changed)
A3: Assumption | B3: Value | C3: Where it comes from
A4: Starting operating cash (AP schedule, 10/22/2026) | B4: 63212 | C4: Bank Balances tab of the AP schedule
A5: Cash floor we never want to go below | B5: 40000 | C5: About 1.5 weeks of payroll + bills
A6: Payroll all in, per month | B6: 128000 | C6: YTD wages $992K + taxes + health + comp, about $122K/mo, plus about $6K/mo of employer taxes not yet on the P&L
A7: Other operating expenses, per month (not payroll, not inventory) | B7: 100000 | C7: FY2026 income statement: total expense less payroll, about $100K/mo (shipping, software, rent, insurance, fees)
A8: Inventory purchases as % of sales | B8: 0.363 | C8: COGS + inbound freight + tariffs = 36.3% of income YTD
A9: Buying cut in Plans B and C (until Jan) | B9: 0.25 | C9: Buy for open orders and top movers only
A10: Software savings per month (Plans B and C) | B10: 4000 | C10: Software runs about $18K/mo; target a 20% cut
A11: Dead stock cash recovered, total (Plans B and C) | B11: 40000 | C11: Sell/return part of $251K with no sales in 12 months; spread over weeks 7 to 13
A12: Credit card paydown per month (Plans A and B) | B12: 5000 | C12: Cards: MC $22.7K + Amex $32.5K
A13: Credit card paydown per month (Plan C) | B13: 10000
A14: Loan payments per month (Ally truck + GM Financial) | B14: 2123 | C14: Ally $1,223/mo actual; GM Financial payment unknown, $900 assumed
A15: Shareholder buyout payments per month | B15: 2000 | C15: $19K paid YTD
A16: Past-due vendor bills at 10/22 | B16: 147789 | C16: AP schedule, oldest is 22 days late
A17: Weeks to catch up past-due bills, Plan A | B17: 13
A18: Weeks to catch up past-due bills, Plan B | B18: 8 | C18: With payment plans agreed on the vendor calls
A19: Weeks to catch up past-due bills, Plan C | B19: 2 | C19: Pay them off with the loan
A20: PayPal Working Capital loan amount (Plan C) | B20: 150000 | C20: PayPal sets the max from PayPal sales volume; check the actual offer
A21: PayPal loan fee (one fixed fee) | B21: 15000 | C21: ASSUMED about 10%. Use the real number from PayPal's offer
A22: Repayment % of PayPal sales | B22: 0.1 | C22: What Marty described
A23: Share of collections that run through PayPal / Payflow | B23: 0.65 | C23: Q3 2026: $823K of $1.26M receipts came in through Payflow
A24: Sales: October 2026 pace, per month | B24: 440000 | C24: Oct 1 to 22 invoiced $311K
A25: Sales: November 2026, per month | B25: 348000 | C25: Nov 2025 ($331K) + 5%
A26: Sales: December 2026, per month | B26: 368000 | C26: Dec 2025 ($350K) + 5%
A27: Sales: January 2027, per month | B27: 385000 | C27: Jan 2026 ($366K) + 5%

Sheet 13-Week Forecast
A1: 13-Week Cash Forecast: The O-Ring Store
A2: Three plans side by side. Change the yellow cells on the Assumptions tab and everything updates.
A4: Week | B4: Wk 1 | C4: Wk 2 | D4: Wk 3 | E4: Wk 4 | F4: Wk 5 | G4: Wk 6 | H4: Wk 7 | I4: Wk 8 | J4: Wk 9 | K4: Wk 10 | L4: Wk 11 | M4: Wk 12 | N4: Wk 13 | O4: 13-wk total
A5: Week starting | B5: 46321 | C5: 46328 | D5: 46335 | E5: 46342 | F5: 46349 | G5: 46356 | H5: 46363 | I5: 46370 | J5: 46377 | K5: 46384 | L5: 46391 | M5: 46398 | N5: 46405
A6: Slow-week factor (1 = normal; monthly pace already includes holidays) | B6: 1 | C6: 1 | D6: 1 | E6: 1 | F6: 1 | G6: 1 | H6: 1 | I6: 1 | J6: 1 | K6: 1 | L6: 1 | M6: 1 | N6: 1
A7: Monthly sales pace used | B7: =Assumptions!$B$24 -> 440000 | C7: =Assumptions!$B$25 -> 348000 | D7: =Assumptions!$B$25 -> 348000 | E7: =Assumptions!$B$25 -> 348000 | F7: =Assumptions!$B$25 -> 348000 | G7: =Assumptions!$B$25 -> 348000 | H7: =Assumptions!$B$26 -> 368000 | I7: =Assumptions!$B$26 -> 368000 | J7: =Assumptions!$B$26 -> 368000 | K7: =Assumptions!$B$26 -> 368000 | L7: =Assumptions!$B$27 -> 385000 | M7: =Assumptions!$B$27 -> 385000 | N7: =Assumptions!$B$27 -> 385000
A8: Expected collections | B8: =B7*12/52*B6 -> 101538.46 | C8: =C7*12/52*C6 -> 80307.692 | D8: =D7*12/52*D6 -> 80307.692 | E8: =E7*12/52*E6 -> 80307.692 | F8: =F7*12/52*F6 -> 80307.692 | G8: =G7*12/52*G6 -> 80307.692 | H8: =H7*12/52*H6 -> 84923.077 | I8: =I7*12/52*I6 -> 84923.077 | ... N8: =N7*12/52*N6 -> 88846.154 | O8: =SUM(B8:N8) -> 1109307.7
A9: Bills already entered and due (wks 1 and 2, AP schedule) | B9: 96289.32 | C9: 44955.26 | D9: 0 | E9: 0 | F9: 0 | G9: 0 | H9: 0 | I9: 0 | J9: 0 | K9: 0 | L9: 0 | M9: 0 | N9: 0
A11: PLAN A: Keep doing what we're doing (no cuts, no loan)
A12: Starting cash | B12: =Assumptions!$B$4 -> 63212 | C12: =B26 -> 25448.988 | D12: =C26 -> 17789.266 | E12: =D26 -> 2856.1892 | F12: =E26 -> -12076.888 | G12: =F26 -> -27009.965 | H12: =G26 -> -41943.042 | I12: =H26 -> -53936.118 | J12: =I26 -> -65929.195 | ... N12: =M26 -> -108903.5
A13: + Customer collections | B13: =B8 -> 101538.46 | C13: =C8 -> 80307.692 | D13: =D8 -> 80307.692 | E13: =E8 -> 80307.692 | F13: =F8 -> 80307.692 | G13: =G8 -> 80307.692 | H13: =H8 -> 84923.077 | I13: =I8 -> 84923.077 | ... N13: =N8 -> 88846.154 | O13: =SUM(B13:N13) -> 1109307.7
A14: + Dead stock sold | B14: 0 | C14: 0 | D14: 0 | E14: 0 | F14: 0 | G14: 0 | H14: 0 | I14: 0 | J14: 0 | K14: 0 | L14: 0 | M14: 0 | N14: 0 | O14: =SUM(B14:N14) -> 0
A15: + PayPal loan | B15: 0 | C15: 0 | D15: 0 | E15: 0 | F15: 0 | G15: 0 | H15: 0 | I15: 0 | J15: 0 | K15: 0 | L15: 0 | M15: 0 | N15: 0 | O15: =SUM(B15:N15) -> 0
A16: Total cash in | B16: =SUM(B13:B15) -> 101538.46 | C16: =SUM(C13:C15) -> 80307.692 | D16: =SUM(D13:D15) -> 80307.692 | E16: =SUM(E13:E15) -> 80307.692 | F16: =SUM(F13:F15) -> 80307.692 | G16: =SUM(G13:G15) -> 80307.692 | H16: =SUM(H13:H15) -> 84923.077 | I16: =SUM(I13:I15) -> 84923.077 | ... N16: =SUM(N13:N15) -> 88846.154 | O16: =SUM(B16:N16) -> 1109307.7
A17: - Payroll | B17: =Assumptions!$B$6*12/52 -> 29538.462 | C17: =Assumptions!$B$6*12/52 -> 29538.462 | D17: =Assumptions!$B$6*12/52 -> 29538.462 | E17: =Assumptions!$B$6*12/52 -> 29538.462 | F17: =Assumptions!$B$6*12/52 -> 29538.462 | G17: =Assumptions!$B$6*12/52 -> 29538.462 | H17: =Assumptions!$B$6*12/52 -> 29538.462 | I17: =Assumptions!$B$6*12/52 -> 29538.462 | ... N17: =Assumptions!$B$6*12/52 -> 29538.462 | O17: =SUM(B17:N17) -> 384000
A18: - Vendor bills and expenses (current) | B18: =B9 -> 96289.32 | C18: =C9 -> 44955.26 | D18: =D8*Assumptions!$B$8+Assumptions!$B$7*12/52 -> 52228.615 | E18: =E8*Assumptions!$B$8+Assumptions!$B$7*12/52 -> 52228.615 | F18: =F8*Assumptions!$B$8+Assumptions!$B$7*12/52 -> 52228.615 | G18: =G8*Assumptions!$B$8+Assumptions!$B$7*12/52 -> 52228.615 | H18: =H8*Assumptions!$B$8+Assumptions!$B$7*12/52 -> 53904 | I18: =I8*Assumptions!$B$8+Assumptions!$B$7*12/52 -> 53904 | J18: =J8*Assumptions!$B$8+Assumptions!$B$7*12/52 -> 53904 | K18: =K8*Assumptions!$B$8+Assumptions!$B$7*12/52 -> 53904 | ... N18: =N8*Assumptions!$B$8+Assumptions!$B$7*12/52 -> 55328.077 | O18: =SUM(B18:N18) -> 731759.27
A19: - Catch up past-due bills | B19: =IF(1<=Assumptions!$B$17,Assumptions!$B$16/Assumptions!$B$17,0) -> 11368.385 | C19: =IF(2<=Assumptions!$B$17,Assumptions!$B$16/Assumptions!$B$17,0) -> 11368.385 | D19: =IF(3<=Assumptions!$B$17,Assumptions!$B$16/Assumptions!$B$17,0) -> 11368.385 | E19: =IF(4<=Assumptions!$B$17,Assumptions!$B$16/Assumptions!$B$17,0) -> 11368.385 | F19: =IF(5<=Assumptions!$B$17,Assumptions!$B$16/Assumptions!$B$17,0) -> 11368.385 | G19: =IF(6<=Assumptions!$B$17,Assumptions!$B$16/Assumptions!$B$17,0) -> 11368.385 | H19: =IF(7<=Assumptions!$B$17,Assumptions!$B$16/Assumptions!$B$17,0) -> 11368.385 | I19: =IF(8<=Assumptions!$B$17,Assumptions!$B$16/Assumptions!$B$17,0) -> 11368.385 | J19: =IF(9<=Assumptions!$B$17,Assumptions!$B$16/Assumptions!$B$17,0) -> 11368.385 | K19: =IF(10<=Assumptions!$B$17,Assumptions!$B$16/Assumptions!$B$17,0) -> 11368.385 | L19: =IF(11<=Assumptions!$B$17,Assumptions!$B$16/Assumptions!$B$17,0) -> 11368.385 | M19: =IF(12<=Assumptions!$B$17,Assumptions!$B$16/Assumptions!$B$17,0) -> 11368.385 | N19: =IF(13<=Assumptions!$B$17,Assumptions!$B$16/Assumptions!$B$17,0) -> 11368.385 | O19: =SUM(B19:N19) -> 147789
A20: - Credit cards | B20: =Assumptions!$B$12*12/52 -> 1153.8462 | C20: =Assumptions!$B$12*12/52 -> 1153.8462 | D20: =Assumptions!$B$12*12/52 -> 1153.8462 | E20: =Assumptions!$B$12*12/52 -> 1153.8462 | F20: =Assumptions!$B$12*12/52 -> 1153.8462 | G20: =Assumptions!$B$12*12/52 -> 1153.8462 | H20: =Assumptions!$B$12*12/52 -> 1153.8462 | I20: =Assumptions!$B$12*12/52 -> 1153.8462 | ... N20: =Assumptions!$B$12*12/52 -> 1153.8462 | O20: =SUM(B20:N20) -> 15000
A21: - Truck/vehicle loans | B21: =Assumptions!$B$14*12/52 -> 489.92308 | C21: =Assumptions!$B$14*12/52 -> 489.92308 | D21: =Assumptions!$B$14*12/52 -> 489.92308 | E21: =Assumptions!$B$14*12/52 -> 489.92308 | F21: =Assumptions!$B$14*12/52 -> 489.92308 | G21: =Assumptions!$B$14*12/52 -> 489.92308 | H21: =Assumptions!$B$14*12/52 -> 489.92308 | I21: =Assumptions!$B$14*12/52 -> 489.92308 | ... N21: =Assumptions!$B$14*12/52 -> 489.92308 | O21: =SUM(B21:N21) -> 6369
A22: - Shareholder buyout | B22: =Assumptions!$B$15*12/52 -> 461.53846 | C22: =Assumptions!$B$15*12/52 -> 461.53846 | D22: =Assumptions!$B$15*12/52 -> 461.53846 | E22: =Assumptions!$B$15*12/52 -> 461.53846 | F22: =Assumptions!$B$15*12/52 -> 461.53846 | G22: =Assumptions!$B$15*12/52 -> 461.53846 | H22: =Assumptions!$B$15*12/52 -> 461.53846 | I22: =Assumptions!$B$15*12/52 -> 461.53846 | ... N22: =Assumptions!$B$15*12/52 -> 461.53846 | O22: =SUM(B22:N22) -> 6000
A23: - PayPal loan repayment | B23: 0 | C23: 0 | D23: 0 | E23: 0 | F23: 0 | G23: 0 | H23: 0 | I23: 0 | J23: 0 | K23: 0 | L23: 0 | M23: 0 | N23: 0 | O23: =SUM(B23:N23) -> 0
A24: Total cash out | B24: =SUM(B17:B23) -> 139301.47 | C24: =SUM(C17:C23) -> 87967.414 | D24: =SUM(D17:D23) -> 95240.769 | E24: =SUM(E17:E23) -> 95240.769 | F24: =SUM(F17:F23) -> 95240.769 | G24: =SUM(G17:G23) -> 95240.769 | H24: =SUM(H17:H23) -> 96916.154 | I24: =SUM(I17:I23) -> 96916.154 | ... N24: =SUM(N17:N23) -> 98340.231 | O24: =SUM(B24:N24) -> 1290917.3
A25: Net for the week | B25: =B16-B24 -> -37763.012 | C25: =C16-C24 -> -7659.7215 | D25: =D16-D24 -> -14933.077 | E25: =E16-E24 -> -14933.077 | F25: =F16-F24 -> -14933.077 | G25: =G16-G24 -> -14933.077 | H25: =H16-H24 -> -11993.077 | I25: =I16-I24 -> -11993.077 | ... N25: =N16-N24 -> -9494.0769 | O25: =SUM(B25:N25) -> -181609.58
A26: Ending cash | B26: =B12+B25 -> 25448.988 | C26: =C12+C25 -> 17789.266 | D26: =D12+D25 -> 2856.1892 | E26: =E12+E25 -> -12076.888 | F26: =F12+F25 -> -27009.965 | G26: =G12+G25 -> -41943.042 | H26: =H12+H25 -> -53936.118 | I26: =I12+I25 -> -65929.195 | ... N26: =N12+N25 -> -118397.58 | O26: =N26 -> -118397.58
A27: PayPal loan still owed | B27: 0 | C27: 0 | D27: 0 | E27: 0 | F27: 0 | G27: 0 | H27: 0 | I27: 0 | J27: 0 | K27: 0 | L27: 0 | M27: 0 | N27: 0
A28: Below the cash floor? | B28: =IF(B26<Assumptions!$B$5,"YES","") -> YES | C28: =IF(C26<Assumptions!$B$5,"YES","") -> YES | D28: =IF(D26<Assumptions!$B$5,"YES","") -> YES | E28: =IF(E26<Assumptions!$B$5,"YES","") -> YES | F28: =IF(F26<Assumptions!$B$5,"YES","") -> YES | G28: =IF(G26<Assumptions!$B$5,"YES","") -> YES | H28: =IF(H26<Assumptions!$B$5,"YES","") -> YES | I28: =IF(I26<Assumptions!$B$5,"YES","") -> YES | ... N28: =IF(N26<Assumptions!$B$5,"YES","") -> YES
A31: PLAN B: Tighten up (buy less, cut software, sell dead stock, vendor payment plans)
A32: Starting cash | B32: =Assumptions!$B$4 -> 63212 | C32: =B46 -> 18343.747 | D32: =C46 -> 3578.7854 | E32: =D46 -> -10248.532 | F32: =E46 -> -24075.849 | G32: =F46 -> -37903.167 | H32: =G46 -> -51730.484 | I32: =H46 -> -56484.669 | J32: =I46 -> -61238.855 | ... N32: =M46 -> -651.05802
A33: + Customer collections | B33: =B8 -> 101538.46 | C33: =C8 -> 80307.692 | D33: =D8 -> 80307.692 | E33: =E8 -> 80307.692 | F33: =F8 -> 80307.692 | G33: =G8 -> 80307.692 | H33: =H8 -> 84923.077 | I33: =I8 -> 84923.077 | ... N33: =N8 -> 88846.154 | O33: =SUM(B33:N33) -> 1109307.7
A34: + Dead stock sold | B34: 0 | C34: 0 | D34: 0 | E34: 0 | F34: 0 | G34: 0 | H34: =Assumptions!$B$11/7 -> 5714.2857 | I34: =Assumptions!$B$11/7 -> 5714.2857 | J34: =Assumptions!$B$11/7 -> 5714.2857 | K34: =Assumptions!$B$11/7 -> 5714.2857 | L34: =Assumptions!$B$11/7 -> 5714.2857 | M34: =Assumptions!$B$11/7 -> 5714.2857 | N34: =Assumptions!$B$11/7 -> 5714.2857 | O34: =SUM(B34:N34) -> 40000
A35: + PayPal loan | B35: 0 | C35: 0 | D35: 0 | E35: 0 | F35: 0 | G35: 0 | H35: 0 | I35: 0 | J35: 0 | K35: 0 | L35: 0 | M35: 0 | N35: 0 | O35: =SUM(B35:N35) -> 0
A36: Total cash in | B36: =SUM(B33:B35) -> 101538.46 | C36: =SUM(C33:C35) -> 80307.692 | D36: =SUM(D33:D35) -> 80307.692 | E36: =SUM(E33:E35) -> 80307.692 | F36: =SUM(F33:F35) -> 80307.692 | G36: =SUM(G33:G35) -> 80307.692 | H36: =SUM(H33:H35) -> 90637.363 | I36: =SUM(I33:I35) -> 90637.363 | ... N36: =SUM(N33:N35) -> 94560.44 | O36: =SUM(B36:N36) -> 1149307.7
A37: - Payroll | B37: =Assumptions!$B$6*12/52 -> 29538.462 | C37: =Assumptions!$B$6*12/52 -> 29538.462 | D37: =Assumptions!$B$6*12/52 -> 29538.462 | E37: =Assumptions!$B$6*12/52 -> 29538.462 | F37: =Assumptions!$B$6*12/52 -> 29538.462 | G37: =Assumptions!$B$6*12/52 -> 29538.462 | H37: =Assumptions!$B$6*12/52 -> 29538.462 | I37: =Assumptions!$B$6*12/52 -> 29538.462 | ... N37: =Assumptions!$B$6*12/52 -> 29538.462 | O37: =SUM(B37:N37) -> 384000
A38: - Vendor bills and expenses (current) | B38: =B9 -> 96289.32 | C38: =C9 -> 44955.26 | D38: =D8*Assumptions!$B$8*(1-Assumptions!$B$9)+Assumptions!$B$7*12/52-Assumptions!$B$10*12/52 -> 44017.615 | E38: =E8*Assumptions!$B$8*(1-Assumptions!$B$9)+Assumptions!$B$7*12/52-Assumptions!$B$10*12/52 -> 44017.615 | F38: =F8*Assumptions!$B$8*(1-Assumptions!$B$9)+Assumptions!$B$7*12/52-Assumptions!$B$10*12/52 -> 44017.615 | G38: =G8*Assumptions!$B$8*(1-Assumptions!$B$9)+Assumptions!$B$7*12/52-Assumptions!$B$10*12/52 -> 44017.615 | H38: =H8*Assumptions!$B$8*(1-Assumptions!$B$9)+Assumptions!$B$7*12/52-Assumptions!$B$10*12/52 -> 45274.154 | I38: =I8*Assumptions!$B$8*(1-Assumptions!$B$9)+Assumptions!$B$7*12/52-Assumptions!$B$10*12/52 -> 45274.154 | J38: =J8*Assumptions!$B$8*(1-Assumptions!$B$9)+Assumptions!$B$7*12/52-Assumptions!$B$10*12/52 -> 45274.154 | K38: =K8*Assumptions!$B$8*(1-Assumptions!$B$9)+Assumptions!$B$7*12/52-Assumptions!$B$10*12/52 -> 45274.154 | ... N38: =N8*Assumptions!$B$8*(1-Assumptions!$B$9)+Assumptions!$B$7*12/52-Assumptions!$B$10*12/52 -> 46342.212 | O38: =SUM(B38:N38) -> 637438.29
A39: - Catch up past-due bills | B39: =IF(1<=Assumptions!$B$18,Assumptions!$B$16/Assumptions!$B$18,0) -> 18473.625 | C39: =IF(2<=Assumptions!$B$18,Assumptions!$B$16/Assumptions!$B$18,0) -> 18473.625 | D39: =IF(3<=Assumptions!$B$18,Assumptions!$B$16/Assumptions!$B$18,0) -> 18473.625 | E39: =IF(4<=Assumptions!$B$18,Assumptions!$B$16/Assumptions!$B$18,0) -> 18473.625 | F39: =IF(5<=Assumptions!$B$18,Assumptions!$B$16/Assumptions!$B$18,0) -> 18473.625 | G39: =IF(6<=Assumptions!$B$18,Assumptions!$B$16/Assumptions!$B$18,0) -> 18473.625 | H39: =IF(7<=Assumptions!$B$18,Assumptions!$B$16/Assumptions!$B$18,0) -> 18473.625 | I39: =IF(8<=Assumptions!$B$18,Assumptions!$B$16/Assumptions!$B$18,0) -> 18473.625 | J39: =IF(9<=Assumptions!$B$18,Assumptions!$B$16/Assumptions!$B$18,0) -> 0 | K39: =IF(10<=Assumptions!$B$18,Assumptions!$B$16/Assumptions!$B$18,0) -> 0 | L39: =IF(11<=Assumptions!$B$18,Assumptions!$B$16/Assumptions!$B$18,0) -> 0 | M39: =IF(12<=Assumptions!$B$18,Assumptions!$B$16/Assumptions!$B$18,0) -> 0 | N39: =IF(13<=Assumptions!$B$18,Assumptions!$B$16/Assumptions!$B$18,0) -> 0 | O39: =SUM(B39:N39) -> 147789
A40: - Credit cards | B40: =Assumptions!$B$12*12/52 -> 1153.8462 | C40: =Assumptions!$B$12*12/52 -> 1153.8462 | D40: =Assumptions!$B$12*12/52 -> 1153.8462 | E40: =Assumptions!$B$12*12/52 -> 1153.8462 | F40: =Assumptions!$B$12*12/52 -> 1153.8462 | G40: =Assumptions!$B$12*12/52 -> 1153.8462 | H40: =Assumptions!$B$12*12/52 -> 1153.8462 | I40: =Assumptions!$B$12*12/52 -> 1153.8462 | ... N40: =Assumptions!$B$12*12/52 -> 1153.8462 | O40: =SUM(B40:N40) -> 15000
A41: - Truck/vehicle loans | B41: =Assumptions!$B$14*12/52 -> 489.92308 | C41: =Assumptions!$B$14*12/52 -> 489.92308 | D41: =Assumptions!$B$14*12/52 -> 489.92308 | E41: =Assumptions!$B$14*12/52 -> 489.92308 | F41: =Assumptions!$B$14*12/52 -> 489.92308 | G41: =Assumptions!$B$14*12/52 -> 489.92308 | H41: =Assumptions!$B$14*12/52 -> 489.92308 | I41: =Assumptions!$B$14*12/52 -> 489.92308 | ... N41: =Assumptions!$B$14*12/52 -> 489.92308 | O41: =SUM(B41:N41) -> 6369
A42: - Shareholder buyout | B42: =Assumptions!$B$15*12/52 -> 461.53846 | C42: =Assumptions!$B$15*12/52 -> 461.53846 | D42: =Assumptions!$B$15*12/52 -> 461.53846 | E42: =Assumptions!$B$15*12/52 -> 461.53846 | F42: =Assumptions!$B$15*12/52 -> 461.53846 | G42: =Assumptions!$B$15*12/52 -> 461.53846 | H42: =Assumptions!$B$15*12/52 -> 461.53846 | I42: =Assumptions!$B$15*12/52 -> 461.53846 | ... N42: =Assumptions!$B$15*12/52 -> 461.53846 | O42: =SUM(B42:N42) -> 6000
A43: - PayPal loan repayment | B43: 0 | C43: 0 | D43: 0 | E43: 0 | F43: 0 | G43: 0 | H43: 0 | I43: 0 | J43: 0 | K43: 0 | L43: 0 | M43: 0 | N43: 0 | O43: =SUM(B43:N43) -> 0
A44: Total cash out | B44: =SUM(B37:B43) -> 146406.71 | C44: =SUM(C37:C43) -> 95072.654 | D44: =SUM(D37:D43) -> 94135.01 | E44: =SUM(E37:E43) -> 94135.01 | F44: =SUM(F37:F43) -> 94135.01 | G44: =SUM(G37:G43) -> 94135.01 | H44: =SUM(H37:H43) -> 95391.548 | I44: =SUM(I37:I43) -> 95391.548 | ... N44: =SUM(N37:N43) -> 77985.981 | O44: =SUM(B44:N44) -> 1196596.3
...

Sheet Vendor Calls
A1: Vendor Call List: sorted by past-due dollars
A2: Goal of each call: thank them, tell them where we are, offer a specific payment date or plan, ask for late fees to be waived. Keep the relationship good.
A4: # | B4: Vendor | C4: Past due | D4: Total open | E4: Days late (oldest) | F4: Bills | G4: Terms | H4: Ask for | I4: Who calls | J4: Promised date / plan | K4: Notes
A5: 1 | B5: Universal Polymer & Rubber, LTD. | C5: 25294 | D5: 27742 | E5: 4 | F5: 4 | G5: Net 30 | H5: Split past due over 4 to 6 weeks; waive late fees; keep current bills on time
A6: 2 | B6: FedEx - 338493479 | C6: 25239.92 | D6: 53641.27 | E6: 20 | F6: 25 | G6: Net 15 | H6: Payment plan on past due; keep shipping account in good standing
A7: 3 | B7: Freudenberg | C7: 19414.5 | D7: 75889.52 | E7: 13 | F7: 76 | G7: Net 30 | H7: Split past due over 4 to 6 weeks; waive late fees; keep current bills on time
A8: 4 | B8: ShipJunction | C8: 16538 | D8: 16538 | E8: 8 | F8: 1 | H8: Payment plan on past due; keep shipping account in good standing
A9: 5 | B9: Seal and Rubber Technologies | C9: 11682.44 | D9: 23787.59 | E9: 19 | F9: 27 | G9: 2% 10 Net 30 | H9: Catch up past due, then pay inside 10 days to get the 2% back
A10: 6 | B10: GE MAO RUBBER INDUSTRIAL CO., LTD . | C10: 9025.74 | D10: 38653.88 | E10: 18 | F10: 53 | G10: Net 30 | H10: Split past due over 4 to 6 weeks; waive late fees; keep current bills on time
A11: 7 | B11: Best Ring Industrial Corporation | C11: 7750 | D11: 7750 | E11: 1 | F11: 1 | G11: ACH Net-30 | H11: Split past due over 4 to 6 weeks; waive late fees; keep current bills on time
A12: 8 | B12: UPS | C12: 7653.4 | D12: 9702.8 | E12: 15 | F12: 8 | G12: ACH | H12: Payment plan on past due; keep shipping account in good standing
A13: 9 | B13: Olypsys | C13: 7500 | D13: 15000 | E13: 22 | F13: 2 | G13: Net 30 | H13: Split past due over 4 to 6 weeks; waive late fees; keep current bills on time
A14: 10 | B14: Splendid Rubber Products Co., Ltd | C14: 5778.02 | D14: 5778.02 | E14: 16 | F14: 3 | G14: Prepaid | H14: Pay past due in next 2 weeks
A15: 11 | B15: Martin B Frostad (Grandpa) | C15: 3650 | D15: 3650 | E15: 2 | F15: 1 | H15: Pay past due in next 2 weeks | K15: Family: Marty's call
A16: 12 | B16: NetSuite | C16: 2219.4 | D16: 2219.4 | E16: 7 | F16: 1 | G16: Net 30 | H16: Pay past due in next 2 weeks
A17: 13 | B17: AnySeals, Inc | C17: 2196.02 | D17: 6984.63 | E17: 14 | F17: 14 | G17: Net 30 | H17: Pay past due in next 2 weeks
A18: 14 | B18: Precision Associates, Inc. | C18: 1181.89 | D18: 1907.12 | E18: 6 | F18: 5 | G18: ACH Net-30 | H18: Pay past due in next 2 weeks
A19: 15 | B19: Port of Whitman County | C19: 1071.51 | D19: 1071.51 | E19: 10 | F19: 1 | G19: COD | H19: Pay past due in next 2 weeks
A20: 16 | B20: Sealcore Operations, LLC | C20: 896.98 | D20: 8132.08 | E20: 13 | F20: 7 | G20: Net 30 | H20: Pay past due in next 2 weeks
A21: 17 | B21: Allied Seals, Inc. | C21: 423.39 | D21: 2808.77 | E21: 14 | F21: 4 | G21: ACH Net-30 | H21: Pay past due in next 2 weeks
A22: 18 | B22: Vulcan Seals | C22: 241.74 | D22: 1564.68 | E22: 6 | F22: 8 | G22: Net 30 | H22: Pay past due in next 2 weeks
A23: 19 | B23: Shamrock Seals | C23: 32.4 | D23: 1033.1 | E23: 11 | F23: 3 | G23: Net 30 | H23: Pay past due in next 2 weeks
A24: 20 | B24: SCS Cloud: Netgain Solutions, Inc. | C24: 0 | D24: 9081.09 | E24: 0 | F24: 1 | G24: Due on receipt | H24: Nothing past due. Pay on time, keep as-is.
A25: 21 | B25: FedEx Logistics | C25: 0 | D25: 5017.37 | E25: 0 | F25: 1 | G25: Net 15 | H25: Nothing past due. Pay on time, keep as-is.
B26: Total | C26: =SUM(C5:C25) -> 147789.35 | D26: =SUM(D5:D25) -> 317952.83
